<robot name="simple_tree">
	<link name = "base">
		<visual name="body_base_mesh">
			<origin rpy = "0 0 0" xyz = "0 0 0"/>
			<geometry>
				<mesh filename="simple-tree/base.STL"/>
			</geometry>
		</visual>	
	</link>
	<link name = "link1">
		<visual name="link1_mesh">
			<origin rpy = "0 0 0" xyz = "0 0 0"/>
			<geometry>
				<mesh filename="simple-tree/link.STL"/>
			</geometry>
		</visual>	
	</link>
	<link name = "link2">
		<visual name="link2_mesh">
			<origin rpy = "0 0 0" xyz = "0 0 0"/>
			<geometry>
				<mesh filename="simple-tree/link.STL"/>
			</geometry>
		</visual>	
	</link>
	<link name = "link3">
		<visual name="link3_mesh">
			<origin rpy = "0 0 0" xyz = "0 0 0"/>
			<geometry>
				<mesh filename="simple-tree/link.STL"/>
			</geometry>
		</visual>	
	</link>
	<link name = "link4">
		<visual name="link4_mesh">
			<origin rpy = "0 0 0" xyz = "0 0 0"/>
			<geometry>
				<mesh filename="simple-tree/link.STL"/>
			</geometry>
		</visual>	
	</link>
	<link name = "link5">
		<visual name="link5_mesh">
			<origin rpy = "0 0 0" xyz = "0 0 0"/>
			<geometry>
				<mesh filename="simple-tree/link.STL"/>
			</geometry>
		</visual>	
	</link>
	<link name = "link6">
		<visual name="link6_mesh">
			<origin rpy = "0 0 0" xyz = "0 0 0"/>
			<geometry>
				<mesh filename="simple-tree/link.STL"/>
			</geometry>
		</visual>	
	</link>
	
	<joint name="j1" type="revolute">
		<parent link="base"/>
		<child link="link1"/>
		<origin rpy = "0 0 0" xyz = "7e-1 12e-1 -0.92e-1"/>
		<axis xyz = "0 0 1"/>
	</joint>
	<joint name="j2" type="revolute">
		<parent link="link1"/>
		<child link="link2"/>
		<origin rpy = "0 0 0" xyz = "20e-1 0 0"/>
		<axis xyz = "0 0 1"/>
	</joint>
	<joint name="j3" type="revolute">
		<parent link="link2"/>
		<child link="link3"/>
		<origin rpy = "0 0 1.57079633" xyz = "20e-1 0 0"/>
		<axis xyz = "0 0 1"/>
	</joint>
	<joint name="j4" type="revolute">
		<parent link="link2"/>
		<child link="link4"/>
		<origin rpy = "0 0 -1.57079633" xyz = "20e-1 0 0"/>
		<axis xyz = "0 0 1"/>
	</joint>

	<joint name="j5" type="revolute">
		<parent link="base"/>
		<child link="link5"/>
		<origin rpy = "0 0 0" xyz = "7e-1 -12e-1 -0.92e-1"/>
		<axis xyz = "0 0 1"/>
	</joint>
	<joint name="j6" type="revolute">
		<parent link="link5"/>
		<child link="link6"/>
		<origin rpy = "0 0 -1.57079633" xyz = "20e-1 0 0"/>
		<axis xyz = "0 0 1"/>
	</joint>
	
</robot>